<?xml version="1.0"?>
<robot name="bbot">
    <link name="base_footprint"/>

    <link name="base_link">
        <visual>
            <origin xyz="0.0 0.0 0.0" rpy="0.0 0.0 0.0"/>
            <geometry>
                <mesh filename="package://bbot_sim/meshes/base_link.STL"/>
            </geometry>
            <material name="LightGrey">
                <color rgba="0.7 0.7 0.7 1.0"/>
            </material>
        </visual>
        <collision>
            <geometry>
                <mesh filename="package://bbot_sim/meshes/base_link.STL"/>
            </geometry>
        </collision>
        <inertial>
            <mass value="0.0"/>
            <origin xyz="0.0 0.0 0.0" rpy="0.0 0.0 0.0"/>
            <inertia ixx="0.0" ixy="0.0" ixz="0.0" iyy="0.0" iyz="0.0" izz="0.0"/>
        </inertial>
    </link>
    <joint name="base_joint" type="fixed">
        <parent link="base_footprint"/>
        <child link="base_link"/>
        <origin xyz="0 0 0.033" rpy="0 0 0"/>
        <axis xyz="0 0 0"/>
    </joint>

    <link name="right_wheel_link">
        <visual>
            <origin xyz="0.0 0.0 0.0" rpy="1.57 0.0 0.0"/>
            <geometry>
                <mesh filename="package://bbot_sim/meshes/wheel_right_link.STL"/>
            </geometry>
            <material name="LightGrey">
                <color rgba="0.7 0.7 0.7 1.0"/>
            </material>
        </visual>
        <collision>
            <geometry>
                <mesh filename="package://bbot_sim/meshes/wheel_right_link.STL"/>
            </geometry>
        </collision>
        <inertial>
            <mass value="0.0"/>
            <origin xyz="0.0 0.0 0.0" rpy="0.0 0.0 0.0"/>
            <inertia ixx="0.0" ixy="0.0" ixz="0.0" iyy="0.0" iyz="0.0" izz="0.0"/>
        </inertial>
    </link>
    <joint name="right_wheel_joint" type="continuous">
        <parent link="base_link"/>
        <child link="right_wheel_link"/>
        <origin xyz="0 -0.07 0" rpy="0 0 0"/>
        <axis xyz="0 1 0"/>
    </joint>

    <link name="left_wheel_link">
        <visual>
            <origin xyz="0.0 0.0 0.0" rpy="-1.57 0.0 0.0"/>
            <geometry>
                <mesh filename="package://bbot_sim/meshes/wheel_left_link.STL"/>
            </geometry>
            <material name="LightGrey">
                <color rgba="0.7 0.7 0.7 1.0"/>
            </material>
        </visual>
        <collision>
            <geometry>
                <mesh filename="package://bbot_sim/meshes/wheel_left_link.STL"/>
            </geometry>
        </collision>
        <inertial>
            <mass value="0.0"/>
            <origin xyz="0.0 0.0 0.0" rpy="0.0 0.0 0.0"/>
            <inertia ixx="0.0" ixy="0.0" ixz="0.0" iyy="0.0" iyz="0.0" izz="0.0"/>
        </inertial>
    </link>
    <joint name="left_wheel_joint" type="continuous">
        <parent link="base_link"/>
        <child link="left_wheel_link"/>
        <origin xyz="0 0.07 0" rpy="0 0 0"/>
        <axis xyz="0 1 0"/>
    </joint>

    <link name="caster_front_link">
        <visual>
            <origin xyz="0.0 0.0 0.0" rpy="0.0 0.0 0.0"/>
            <geometry>
                <mesh filename="package://bbot_sim/meshes/caster_front_link.STL"/>
            </geometry>
            <material name="LightGrey">
                <color rgba="0.7 0.7 0.7 1.0"/>
            </material>
        </visual>
        <collision>
            <geometry>
                <mesh filename="package://bbot_sim/meshes/caster_front_link.STL"/>
            </geometry>
        </collision>
        <inertial>
            <mass value="0.0"/>
            <origin xyz="0.0 0.0 0.0" rpy="0.0 0.0 0.0"/>
            <inertia ixx="0.0" ixy="0.0" ixz="0.0" iyy="0.0" iyz="0.0" izz="0.0"/>
        </inertial>
    </link>
    <joint name="caster_front_joint" type="fixed">
        <parent link="base_link"/>
        <child link="caster_front_link"/>
        <origin xyz="0.0475 0.0 -0.0275" rpy="0 0 0"/>
        <axis xyz="0 0 0"/>
    </joint>

    <link name="caster_rear_link">
        <visual>
            <origin xyz="0.0 0.0 0.0" rpy="0.0 0.0 0.0"/>
            <geometry>
                <mesh filename="package://bbot_sim/meshes/caster_rear_link.STL"/>
            </geometry>
            <material name="LightGrey">
                <color rgba="0.7 0.7 0.7 1.0"/>
            </material>
        </visual>
        <collision>
            <geometry>
                <mesh filename="package://bbot_sim/meshes/caster_rear_link.STL"/>
            </geometry>
        </collision>
        <inertial>
            <mass value="0.0"/>
            <origin xyz="0.0 0.0 0.0" rpy="0.0 0.0 0.0"/>
            <inertia ixx="0.0" ixy="0.0" ixz="0.0" iyy="0.0" iyz="0.0" izz="0.0"/>
        </inertial>
    </link>
    <joint name="caster_rear_joint" type="fixed">
        <parent link="base_link"/>
        <child link="caster_rear_link"/>
        <origin xyz="-0.0475 0.0 -0.0275" rpy="0 0 0"/>
        <axis xyz="0 0 0"/>
    </joint>

</robot>